(Pdb) p res_group
Date/time | 2025-01-09T18:13:20.285256+09:00[Asia/Tokyo]
User      | derekwan
Host      | DW-Mac
Version   | 0.90.12-dirty

Exception group:
    Frame 1/1: func_task_group_one_first (tests.test_traceback_funcs.task_group_one)
        Inputs:
            args[0] = 1
            args[1] = 2
            args[2] = 3
            args[3] = 4
            kwargs = 5
            kwargs = 6
            kwargs = 7
        Locals:
            a = 2
            b = 4
            c = 10
            args = (6, 8)
            kwargs = {'d': 12, 'e': 14}
            tg = <TaskGroup cancelling>
            _ = <Task finished name='Task-2' coro=<func_task_group_one_second() done, defined at
/Users/derekwan/work/python-utilities2/src/utilities/traceback.py:603> exception=AssertionError('Result (112) must be divisible by
10')>
        Line 18:
            async with TaskGroup() as tg:
        Raised:
            ExceptionGroup(unhandled errors in a TaskGroup (1 sub-exception))

    Exception group 1/1:
    Frame 1/1: func_task_group_one_second (tests.test_traceback_funcs.task_group_one)
        Inputs:
            args[0] = 2
            args[1] = 4
            args[2] = 6
            args[3] = 8
            kwargs = 10
            kwargs = 12
            kwargs = 14
        Locals:
            a = 4
            b = 8
            c = 20
            args = (12, 16)
            kwargs = {'d': 24, 'e': 28}
            result = 112
        Line 33:
            assert result % 10 == 0, f"Result ({result}) must be divisible by 10"
        Raised:
            AssertionError(Result (112) must be divisible by 10)
